<?xml version="1.0"?>
<robot xmlns:xacro="http://www.ros.org/wiki/xacro" name="rover">
 
  
 <link name="base_footprint">
 

</link>
  <link name="base_link">
     <inertial>
        <origin xyz="0 0 0" rpy="0 0 0"/>
        <mass value="1.0"/>
       <inertia ixx="0.0395416666667" ixy="0" ixz="0"     iyy="0.106208333333" iyz="0" izz="0.106208333333"/>    
  </inertial>
    <visual>
      <geometry>
        <box size=".8 .7 .1"/>
       </geometry>
       <material name="blue">
           <color rgba="0 0 .8 1"/>
         </material>
    </visual>
  </link>


<joint name="base_joint" type="fixed">
    <origin xyz="0.0 0.0 0.135" rpy="0.0 0.0 0.0"/>
    <parent link="base_footprint"/>
    <child link="base_link"/>
    <axis xyz="0.0 0.0 0.0"/>
 </joint>



<link name="camera">
  <visual>
    <geometry>
       <box size="0.1 0.25 0.1" />
     </geometry>
    <material name="LightGrey">
      <color rgba="0.7 0.7 0.7 1.0"/>
    </material>
  </visual>
  <collision>
    <geometry>
       <box size="0.01 0.01 0.01" />
     </geometry>
  </collision>
  <inertial>
    <mass value="0.004"/>
    <origin xyz="0.0 0.0 0.0" rpy="0.0 0.0 0.0"/>
    <inertia ixx="0.0" ixy="0.0" ixz="0.0" iyy="0.0" iyz="0.0" izz="0.0"/>
  </inertial>
</link>

<joint name="camera_joint" type="fixed">
  <origin xyz="0.35 0.0 0.1" rpy="0.0 0.0 0.0"/>
  <parent link="base_link"/>
  <child link="camera"/>
  <axis xyz="0.0 0.0 0.0"/>
  <limit lower="0.0" upper="0.0" effort="0.0" velocity="0.0"/>
</joint>


<link name="hole">
  <visual>
    <geometry>
       <cylinder radius="0.035" length="0.1"/>
    </geometry>
    <material name="black">
          <color rgba="0 0 0 1.0"/>
    </material>
  </visual>
  <collision>
    <geometry>
       <cylinder radius="0.035" length="0.4"/>
    </geometry>
  </collision>
  <inertial>
    <mass value="0.04"/>
    <origin xyz="0.0 0.0 0.0" rpy="0.0 0.0 0.0"/>
    <inertia ixx="0.0" ixy="0.0" ixz="0.0" iyy="0.0" iyz="0.0" izz="0.0"/>
  </inertial>
</link>

<joint name="hole_joint" type="fixed">
  <parent link="camera"/>
  <child link="hole"/>
  <origin xyz="0.01 0.0 0.005" rpy="0.0 1.6 0.0"/>
</joint>


<link name="board">
  <visual>
    <geometry>
       <box size="0.25 0.25 0.12" />
     </geometry>
    <material name="blue">
           <color rgba="0 0 .8 1"/>
    </material>
  </visual>
  <collision>
    <geometry>
       <box size="0.01 0.01 0.01" />
     </geometry>
  </collision>
  <inertial>
    <mass value="0.004"/>
    <origin xyz="0.0 0.0 0.0" rpy="0.0 0.0 0.0"/>
    <inertia ixx="0.0" ixy="0.0" ixz="0.0" iyy="0.0" iyz="0.0" izz="0.0"/>
  </inertial>
</link>

<joint name="board_joint" type="fixed">
  <origin xyz="0.0 0.0 0.1" rpy="0.0 0.0 0.0"/>
  <parent link="base_link"/>
  <child link="board"/>
  <axis xyz="0.0 0.0 0.0"/>
  <limit lower="0.0" upper="0.0" effort="0.0" velocity="0.0"/>
</joint>

<link name="laser_frame">
  <visual>
    <geometry>
      <cylinder radius="0.06" length="0.09"/>
      </geometry>
    <material name="red">
           <color rgba="0.8 0 0 1"/>
    </material>
  </visual>
  <collision>
    <geometry>
      <cylinder radius="0.06" length="0.09"/>
     </geometry>
  </collision>
  <inertial>
    <mass value="0.004"/>
    <origin xyz="0.0 0.0 0.0" rpy="0.0 0.0 0.0"/>
    <inertia ixx="0.0" ixy="0.0" ixz="0.0" iyy="0.0" iyz="0.0" izz="0.0"/>
  </inertial>
</link>

<joint name="laser_joint" type="fixed">
  <origin xyz="0.0 0.0 0.1" rpy="0.0 0.0 0.0"/>
  <parent link="board"/>
  <child link="laser_frame"/>
  <axis xyz="0.0 0.0 0.0"/>
  <limit lower="0.0" upper="0.0" effort="0.0" velocity="0.0"/>
</joint>

<xacro:macro name="wheel_right" params="name x y">
    <link name="wheel_${name}_link">
      <inertial>
        <origin xyz="0 0 0" rpy="0 0 0"/>
        <mass value="0.5"/>
<inertia ixx="0.00052666666" ixy="0" ixz="0" iyy="0.00052666666" iyz="0" izz="0.001"/>       </inertial>

      <visual>
        <origin xyz="0 0 0" rpy="0 0 0" />
        <geometry>
        <mesh filename="package://rover/meshes/right_tire.stl" scale="0.0045 0.0045 0.0045"/>
                <cylinder radius="0.0" length="0.0"/>

          </geometry>
        <material name="black">
          <color rgba="0 0 0 1.0"/>
        </material>
      </visual>

      <collision>
        <origin xyz="0 0 0" rpy="0 0 0"/>
        <geometry>
        <mesh filename="package://rover/meshes/right_tire.stl" scale="0.0045 0.0045 0.0045"/>
                <cylinder radius="0.0" length="0.0"/>

        </geometry>
      </collision>
    </link>

    <joint name="wheel_${name}_joint" type="continuous">
        <origin xyz="${x} ${y} 0.0" rpy="0 0.0 0.0"/>
        <parent link="base_link"/>
        <child link="wheel_${name}_link"/>
        <axis xyz="0.0 1.0 0.0"/>
        <!-- <limit lower="0.0" upper="0.0" effort="0.0" velocity="0.0"/> -->
    </joint>
  
</xacro:macro>

<xacro:macro name="wheel_left" params="name x y">
    <link name="wheel_${name}_link">
      <inertial>
        <origin xyz="0 0 0" rpy="0 0 0"/>
        <mass value="0.5"/>
<inertia ixx="0.00052666666" ixy="0" ixz="0" iyy="0.00052666666" iyz="0" izz="0.001"/>       </inertial>

      <visual>
        <origin xyz="0 0 0" rpy="0 0 0" />
        <geometry>
        <mesh filename="package://rover/meshes/left_tire.stl" scale="0.0045 0.0045 0.0045"/>
        <cylinder radius="0.0" length="0.0"/>
           </geometry>
        <material name="black">
          <color rgba="0 0 0 1.0"/>
        </material>
      </visual>

      <collision>
        <origin xyz="0 0 0" rpy="0 0 0"/>
        <geometry>
        <mesh filename="package://rover/meshes/left_tire.stl" scale="0.0045 0.0045 0.0045"/>
                <cylinder radius="0.0" length="0.0"/>

        </geometry>
      </collision>
    </link>

    <joint name="wheel_${name}_joint" type="continuous">
        <origin xyz="${x} ${y} 0.0" rpy="0 0.0 0.0"/>
        <parent link="base_link"/>
        <child link="wheel_${name}_link"/>
        <axis xyz="0.0 1.0 0.0"/>
        <!-- <limit lower="0.0" upper="0.0" effort="0.0" velocity="0.0"/> -->
    </joint>
  
</xacro:macro>

 

<xacro:wheel_left name="front_left" x="-0.25" y="-0.40"/>
<xacro:wheel_right name="front_right" x="-0.25" y="0.40"/>
<xacro:wheel_left name="rear_left" x="0.25" y="-0.40"/>
<xacro:wheel_right name="rear_right" x="0.25" y="0.40"/>


<gazebo reference="laser_frame">
    <material>Gazebo/Red</material>
  </gazebo>

<gazebo reference="board">
    <material>Gazebo/Blue</material>
  </gazebo>

 <gazebo reference="camera">
    <material>Gazebo/Orange</material>
  </gazebo>

   <gazebo reference="hole">
    <material>Gazebo/Black</material>
  </gazebo>

   <gazebo reference="base_link">
    <material>Gazebo/Blue</material>
  </gazebo>

<gazebo reference="wheel_front_left_link">
    <material>Gazebo/Black</material>
  </gazebo>

<gazebo reference="wheel_front_right_link">
    <material>Gazebo/Black</material>
  </gazebo>

<gazebo reference="wheel_rear_left_link">
    <material>Gazebo/Black</material>
  </gazebo>

<gazebo reference="wheel_rear_right_link">
    <material>Gazebo/Black</material>
  </gazebo>

<transmission name="wheel_rear_right_joint">
  <type>transmission_interface/SimpleTransmission</type>
    
  <joint name="wheel_rear_right_joint">
    <hardwareInterface>
      hardware_interface/VelocityJointInterface
    </hardwareInterface>      
  </joint> 
   
  <actuator name="wheel_rear_right_joint">        
    <mechanicalReduction>1</mechanicalReduction>    
    <hardwareInterface>
      VelocityJointInterface
    </hardwareInterface>   
  </actuator> 
 
</transmission>

<transmission name="wheel_rear_left_joint">
  <type>transmission_interface/SimpleTransmission</type>
    
  <joint name="wheel_rear_left_joint">
    <hardwareInterface>
      hardware_interface/VelocityJointInterface
    </hardwareInterface>      
  </joint> 
   
  <actuator name="wheel_rear_left_joint">        
    <mechanicalReduction>1</mechanicalReduction>    
    <hardwareInterface>
      VelocityJointInterface
    </hardwareInterface>   
  </actuator> 
 
</transmission>

<transmission name="wheel_front_left_joint">
  <type>transmission_interface/SimpleTransmission</type>
    
  <joint name="wheel_front_left_joint">
    <hardwareInterface>
      hardware_interface/VelocityJointInterface
    </hardwareInterface>      
  </joint> 
   
  <actuator name="wheel_front_left_joint">        
    <mechanicalReduction>1</mechanicalReduction>    
    <hardwareInterface>
      VelocityJointInterface
    </hardwareInterface>   
  </actuator> 
 
</transmission>

<transmission name="wheel_front_right_joint">
  <type>transmission_interface/SimpleTransmission</type>
    
  <joint name="wheel_front_right_joint">
    <hardwareInterface>
      hardware_interface/VelocityJointInterface
    </hardwareInterface>      
  </joint> 
   
  <actuator name="wheel_front_right_joint">        
    <mechanicalReduction>1</mechanicalReduction>    
    <hardwareInterface>
      VelocityJointInterface
    </hardwareInterface>   
  </actuator> 
 
</transmission>

<gazebo> 
  <plugin name="gazebo_ros_control" filename="libgazebo_ros_control.so"> 
    </plugin>
</gazebo>


 <gazebo reference="camera">
    <sensor type="camera" name="camera1">
    <visualize>true</visualize>
      <update_rate>30.0</update_rate>
      <camera name="head">
        <horizontal_fov>1.3962634</horizontal_fov>
        <image>
          <width>1024</width>
          <height>1024</height>
          <format>R8G8B8</format>
        </image>
        <clip>
          <near>0.02</near>
          <far>7</far>
        </clip>
        <noise>
          <type>gaussian</type>
          <!-- Noise is sampled independently per pixel on each frame.
               That pixel's noise value is added to each of its color
               channels, which at that point lie in the range [0,1]. -->
          <mean>0.0</mean>
          <stddev>0.007</stddev>
        </noise>
      </camera>
      <plugin name="camera_controller" filename="libgazebo_ros_camera.so">
        <alwaysOn>true</alwaysOn>
        <updateRate>0.0</updateRate>
        <cameraName>camera1</cameraName>
        <imageTopicName>image_raw</imageTopicName>
        <cameraInfoTopicName>camera_info</cameraInfoTopicName>
        <frameName>camera_link</frameName>
        <hackBaseline>0.07</hackBaseline>
        <distortionK1>0.0</distortionK1>
        <distortionK2>0.0</distortionK2>
        <distortionK3>0.0</distortionK3>
        <distortionT1>0.0</distortionT1>
        <distortionT2>0.0</distortionT2>
      </plugin>
    </sensor>
  </gazebo>


  <gazebo reference="laser_frame">
    <sensor type="ray" name="laser">
      <pose>0 0 0 0 0 0</pose>
      <visualize>true</visualize>
      <update_rate>40</update_rate>
      <ray>
        <scan>
          <horizontal>
            <samples>360</samples>
            <resolution>1</resolution>
            <min_angle>-3.14</min_angle>
            <max_angle>3.14</max_angle>
          </horizontal>
        </scan>
        <range>
          <min>0.80</min>
          <max>12.0</max>
          <resolution>0.4</resolution>
        </range>
        <noise>
          <type>gaussian</type>
          <!-- Noise parameters based on published spec for Hokuyo laser
               achieving "+-30mm" accuracy at range < 10m.  A mean of 0.0m and
               stddev of 0.01m will put 99.7% of samples within 0.03m of the true
               reading. -->
          <mean>0.0</mean>
          <stddev>0.01</stddev>
        </noise>
      </ray>
 <plugin name="gazebo_ros_head_hokuyo_controller" filename="libgazebo_ros_laser.so">         <topicName>/laser/scan</topicName>
        <frameName>laser_frame</frameName>
      </plugin>
    </sensor>
  </gazebo>

</robot>


